Workbook
Name UPDATE: 'Data Sheet'!$E$1

Sheet Ratio Analysis
B2: ="Ratio Analysis - "&'Data Sheet'!B1 -> Ratio Analysis - ASIAN PAINTS LTD
B3: Years | C3: ='Data Sheet'!B16 -> 42460 | D3: ='Data Sheet'!C16 -> 42825 | E3: ='Data Sheet'!D16 -> 43190 | F3: ='Data Sheet'!E16 -> 43555 | G3: ='Data Sheet'!F16 -> 43921 | H3: ='Data Sheet'!G16 -> 44286 | I3: ='Data Sheet'!H16 -> 44651 | J3: ='Data Sheet'!I16 -> 45016 | ... L3: ='Data Sheet'!K16 -> 45747 | M3: Trend | N3: Mean | O3: Median
B5: Sales Growth | D5: =IFERROR(HistoricalFS!D7,0) -> -0.73845717 | E5: =IFERROR(HistoricalFS!E7,0) -> 0.11702039 | F5: =IFERROR(HistoricalFS!F7,0) -> 0.14357472 | G5: =IFERROR(HistoricalFS!G7,0) -> 0.050473671 | H5: =IFERROR(HistoricalFS!H7,0) -> 0.074292288 | I5: =IFERROR(HistoricalFS!I7,0) -> 0.34028285 | J5: =IFERROR(HistoricalFS!J7,0) -> 0.18512278 | K5: =IFERROR(HistoricalFS!K7,0) -> 0.029173127 | L5: =IFERROR(HistoricalFS!L7,0) -> -0.044770308 | N5: =IFERROR(AVERAGE(D5:L5),0) -> 0.017412483 | O5: =IFERROR(MEDIAN(C5:L5),0) -> 0.074292288
B6: EBITDA Growth | D6: =IFERROR(HistoricalFS!D18/HistoricalFS!C18-1,0) -> -0.93497841 | E6: =IFERROR(HistoricalFS!E18/HistoricalFS!D18-1,0) -> 0.070229411 | F6: =IFERROR(HistoricalFS!F18/HistoricalFS!E18-1,0) -> 0.17507124 | G6: =IFERROR(HistoricalFS!G18/HistoricalFS!F18-1,0) -> 0.10540141 | H6: =IFERROR(HistoricalFS!H18/HistoricalFS!G18-1,0) -> 0.16671512 | I6: =IFERROR(HistoricalFS!I18/HistoricalFS!H18-1,0) -> -0.010707225 | J6: =IFERROR(HistoricalFS!J18/HistoricalFS!I18-1,0) -> 0.30315325 | K6: =IFERROR(HistoricalFS!K18/HistoricalFS!J18-1,0) -> 0.21168912 | L6: =IFERROR(HistoricalFS!L18/HistoricalFS!K18-1,0) -> -0.20814425 | N6: =IFERROR(AVERAGE(D6:L6),0) -> -0.013507814 | O6: =IFERROR(MEDIAN(C6:L6),0) -> 0.10540141
B7: EBIT Growth | D7: =IFERROR(HistoricalFS!D27/HistoricalFS!C27-1,0) -> -0.94265625 | E7: =IFERROR(HistoricalFS!E27/HistoricalFS!D27-1,0) -> 0.068823332 | F7: =IFERROR(HistoricalFS!F27/HistoricalFS!E27-1,0) -> 0.082174964 | G7: =IFERROR(HistoricalFS!G27/HistoricalFS!F27-1,0) -> 0.0813269 | H7: =IFERROR(HistoricalFS!H27/HistoricalFS!G27-1,0) -> 0.21158057 | I7: =IFERROR(HistoricalFS!I27/HistoricalFS!H27-1,0) -> -0.020353915 | J7: =IFERROR(HistoricalFS!J27/HistoricalFS!I27-1,0) -> 0.35087003 | K7: =IFERROR(HistoricalFS!K27/HistoricalFS!J27-1,0) -> 0.24145913 | L7: =IFERROR(HistoricalFS!L27/HistoricalFS!K27-1,0) -> -0.27179587 | N7: =IFERROR(AVERAGE(D7:L7),0) -> -0.022063456 | O7: =IFERROR(MEDIAN(C7:L7),0) -> 0.0813269
B8: Net Profit Growth | D8: =IFERROR(HistoricalFS!D33/HistoricalFS!C33-1,0) -> -0.96259818 | E8: =IFERROR(HistoricalFS!E33/HistoricalFS!D33-1,0) -> 0.049310335 | F8: =IFERROR(HistoricalFS!F33/HistoricalFS!E33-1,0) -> 0.098324352 | G8: =IFERROR(HistoricalFS!G33/HistoricalFS!F33-1,0) -> 0.25323249 | H8: =IFERROR(HistoricalFS!H33/HistoricalFS!G33-1,0) -> 0.18605332 | I8: =IFERROR(HistoricalFS!I33/HistoricalFS!H33-1,0) -> -0.029971131 | J8: =IFERROR(HistoricalFS!J33/HistoricalFS!I33-1,0) -> 0.34957493 | K8: =IFERROR(HistoricalFS!K33/HistoricalFS!J33-1,0) -> 0.25847333 | L8: =IFERROR(HistoricalFS!L33/HistoricalFS!K33-1,0) -> -0.29075755 | N8: =IFERROR(AVERAGE(D8:L8),0) -> -0.0098175674 | O8: =IFERROR(MEDIAN(C8:L8),0) -> 0.098324352
B9: Dividend Growth | D9: =IFERROR(HistoricalFS!D41/HistoricalFS!C41-1,0) -> 0.37333889 | E9: =IFERROR(HistoricalFS!E41/HistoricalFS!D41-1,0) -> -0.15534727 | F9: =IFERROR(HistoricalFS!F41/HistoricalFS!E41-1,0) -> 0.20690234 | G9: =IFERROR(HistoricalFS!G41/HistoricalFS!F41-1,0) -> 0.14285714 | H9: =IFERROR(HistoricalFS!H41/HistoricalFS!G41-1,0) -> 0.48749826 | I9: =IFERROR(HistoricalFS!I41/HistoricalFS!H41-1,0) -> 0.072831553 | J9: =IFERROR(HistoricalFS!J41/HistoricalFS!I41-1,0) -> 0.33942522 | K9: =IFERROR(HistoricalFS!K41/HistoricalFS!J41-1,0) -> 0.29824618 | L9: =IFERROR(HistoricalFS!L41/HistoricalFS!K41-1,0) -> -0.25525494 | N9: =IFERROR(AVERAGE(D9:L9),0) -> 0.16783304 | O9: =IFERROR(MEDIAN(C9:L9),0) -> 0.20690234
B11: Gross Margin | C11: =IFERROR(HistoricalFS!C13,0) -> 0.83653406 | D11: =IFERROR(HistoricalFS!D13,0) -> 0.35382642 | E11: =IFERROR(HistoricalFS!E13,0) -> 0.33465264 | F11: =IFERROR(HistoricalFS!F13,0) -> 0.32922439 | G11: =IFERROR(HistoricalFS!G13,0) -> 0.34897545 | H11: =IFERROR(HistoricalFS!H13,0) -> 0.35360357 | I11: =IFERROR(HistoricalFS!I13,0) -> 0.2924514 | J11: =IFERROR(HistoricalFS!J13,0) -> 0.31088224 | ... L11: =IFERROR(HistoricalFS!L13,0) -> 0.32927727 | N11: =IFERROR(AVERAGE(C11:L11),0) -> 0.38411625 | O11: =IFERROR(MEDIAN(C11:L11),0) -> 0.34181404
B12: EBITDA Margin | C12: =IFERROR(HistoricalFS!C19,0) -> 0.79950251 | D12: =IFERROR(HistoricalFS!D19,0) -> 0.19876258 | E12: =IFERROR(HistoricalFS!E19,0) -> 0.19043659 | F12: =IFERROR(HistoricalFS!F19,0) -> 0.19568163 | G12: =IFERROR(HistoricalFS!G19,0) -> 0.20591354 | H12: =IFERROR(HistoricalFS!H19,0) -> 0.22362856 | I12: =IFERROR(HistoricalFS!I19,0) -> 0.16506525 | J12: =IFERROR(HistoricalFS!J19,0) -> 0.18150467 | ... L12: =IFERROR(HistoricalFS!L19,0) -> 0.17714497 | N12: =IFERROR(AVERAGE(C12:L12),0) -> 0.25513334 | O12: =IFERROR(MEDIAN(C12:L12),0) -> 0.19722211
B13: EBIT Margin | C13: =IFERROR((HistoricalFS!C18-HistoricalFS!C24)/HistoricalFS!C6,0) -> 0.79471722 | D13: =IFERROR((HistoricalFS!D18-HistoricalFS!D24)/HistoricalFS!D6,0) -> 0.17653511 | E13: =IFERROR((HistoricalFS!E18-HistoricalFS!E24)/HistoricalFS!E6,0) -> 0.16901136 | F13: =IFERROR((HistoricalFS!F18-HistoricalFS!F24)/HistoricalFS!F6,0) -> 0.16334609 | G13: =IFERROR((HistoricalFS!G18-HistoricalFS!G24)/HistoricalFS!G6,0) -> 0.16729643 | H13: =IFERROR((HistoricalFS!H18-HistoricalFS!H24)/HistoricalFS!H6,0) -> 0.18718599 | I13: =IFERROR((HistoricalFS!I18-HistoricalFS!I24)/HistoricalFS!I6,0) -> 0.13701287 | J13: =IFERROR((HistoricalFS!J18-HistoricalFS!J24)/HistoricalFS!J6,0) -> 0.15662629 | ... L13: =IFERROR((HistoricalFS!L18-HistoricalFS!L24)/HistoricalFS!L6,0) -> 0.14687447 | N13: =IFERROR(AVERAGE(C13:L13),0) -> 0.22882672 | O13: =IFERROR(MEDIAN(C13:L13),0) -> 0.16815389
B14: EBT Margin | C14: =IFERROR(HistoricalFS!C28,0) -> 0.79386636 | D14: =IFERROR(HistoricalFS!D28,0) -> 0.17405668 | E14: =IFERROR(HistoricalFS!E28,0) -> 0.1665465 | F14: =IFERROR(HistoricalFS!F28,0) -> 0.15760444 | G14: =IFERROR(HistoricalFS!G28,0) -> 0.16223341 | H14: =IFERROR(HistoricalFS!H28,0) -> 0.18296589 | I14: =IFERROR(HistoricalFS!I28,0) -> 0.13373432 | J14: =IFERROR(HistoricalFS!J28,0) -> 0.15243795 | ... L14: =IFERROR(HistoricalFS!L28,0) -> 0.14017883 | N14: =IFERROR(AVERAGE(C14:L14),0) -> 0.22475055 | O14: =IFERROR(MEDIAN(C14:L14),0) -> 0.16438996
B15: Net Profit Margin | C15: =IFERROR(HistoricalFS!C34,0) -> 0.77920228 | D15: =IFERROR(HistoricalFS!D34,0) -> 0.1114295 | E15: =IFERROR(HistoricalFS!E34,0) -> 0.10467501 | F15: =IFERROR(HistoricalFS!F34,0) -> 0.1005331 | G15: =IFERROR(HistoricalFS!G34,0) -> 0.11993766 | H15: =IFERROR(HistoricalFS!H34,0) -> 0.13241504 | I15: =IFERROR(HistoricalFS!I34,0) -> 0.095835303 | J15: =IFERROR(HistoricalFS!J34,0) -> 0.10913377 | ... L15: =IFERROR(HistoricalFS!L34,0) -> 0.099083574 | N15: =IFERROR(AVERAGE(C15:L15),0) -> 0.17856941 | O15: =IFERROR(MEDIAN(C15:L15),0) -> 0.11028164
B17: Sales Expenses%Sales | C17: =IFERROR(HistoricalFS!C16,0) -> 0.037031551 | D17: =IFERROR(HistoricalFS!D16,0) -> 0.15506384 | E17: =IFERROR(HistoricalFS!E16,0) -> 0.14421604 | F17: =IFERROR(HistoricalFS!F16,0) -> 0.13354276 | G17: =IFERROR(HistoricalFS!G16,0) -> 0.14306191 | H17: =IFERROR(HistoricalFS!H16,0) -> 0.12997501 | I17: =IFERROR(HistoricalFS!I16,0) -> 0.12738615 | J17: =IFERROR(HistoricalFS!J16,0) -> 0.12937757 | ... L17: =IFERROR(HistoricalFS!L16,0) -> 0.1521323 | N17: =IFERROR(AVERAGE(C17:L17),0) -> 0.1289829 | O17: =IFERROR(MEDIAN(C17:L17),0) -> 0.13579233
B18: Depreciation%Sales | C18: =IFERROR(HistoricalFS!C25,0) -> 0.0047852889 | D18: =IFERROR(HistoricalFS!D25,0) -> 0.022227475 | E18: =IFERROR(HistoricalFS!E25,0) -> 0.021425239 | F18: =IFERROR(HistoricalFS!F25,0) -> 0.03233554 | G18: =IFERROR(HistoricalFS!G25,0) -> 0.038617107 | H18: =IFERROR(HistoricalFS!H25,0) -> 0.036442576 | I18: =IFERROR(HistoricalFS!I25,0) -> 0.028052374 | J18: =IFERROR(HistoricalFS!J25,0) -> 0.024878373 | ... L18: =IFERROR(HistoricalFS!L25,0) -> 0.030270498 | N18: =IFERROR(AVERAGE(C18:L18),0) -> 0.026306621 | O18: =IFERROR(MEDIAN(C18:L18),0) -> 0.026465374
B19: OperatingIncome%Sales | C19: =C13 -> 0.79471722 | D19: =D13 -> 0.17653511 | E19: =E13 -> 0.16901136 | F19: =F13 -> 0.16334609 | G19: =G13 -> 0.16729643 | H19: =H13 -> 0.18718599 | I19: =I13 -> 0.13701287 | J19: =J13 -> 0.15662629 | ... L19: =L13 -> 0.14687447 | N19: =IFERROR(AVERAGE(C19:L19),0) -> 0.22882672 | O19: =IFERROR(MEDIAN(C19:L19),0) -> 0.16815389
B21: Return on Capital Employed | C21: =IFERROR((HistoricalFS!C18-HistoricalFS!C24)/(SUM(HistoricalFS!C47:C49)),0) -> 6.6831535 | D21: =IFERROR((HistoricalFS!D18-HistoricalFS!D24)/(SUM(HistoricalFS!D47:D49)),0) -> 0.32568534 | E21: =IFERROR((HistoricalFS!E18-HistoricalFS!E24)/(SUM(HistoricalFS!E47:E49)),0) -> 0.31793919 | F21: =IFERROR((HistoricalFS!F18-HistoricalFS!F24)/(SUM(HistoricalFS!F47:F49)),0) -> 0.29126565 | G21: =IFERROR((HistoricalFS!G18-HistoricalFS!G24)/(SUM(HistoricalFS!G47:G49)),0) -> 0.30059314 | H21: =IFERROR((HistoricalFS!H18-HistoricalFS!H24)/(SUM(HistoricalFS!H47:H49)),0) -> 0.29241025 | I21: =IFERROR((HistoricalFS!I18-HistoricalFS!I24)/(SUM(HistoricalFS!I47:I49)),0) -> 0.25893857 | J21: =IFERROR((HistoricalFS!J18-HistoricalFS!J24)/(SUM(HistoricalFS!J47:J49)),0) -> 0.30135929 | ... L21: =IFERROR((HistoricalFS!L18-HistoricalFS!L24)/(SUM(HistoricalFS!L47:L49)),0) -> 0.22959184 | N21: =IFERROR(AVERAGE(C21:L21),0) -> 0.93184428 | O21: =IFERROR(MEDIAN(C21:L21),0) -> 0.30097621
B22: Retained Earnings% | C22: =IFERROR(HistoricalFS!C44,0) -> 0.98396826 | D22: =IFERROR(HistoricalFS!D44,0) -> 0.41133852 | E22: =IFERROR(HistoricalFS!E44,0) -> 0.52615112 | F22: =IFERROR(HistoricalFS!F44,0) -> 0.47930744 | G22: =IFERROR(HistoricalFS!G44,0) -> 0.52516614 | H22: =IFERROR(HistoricalFS!H44,0) -> 0.40448332 | I22: =IFERROR(HistoricalFS!I44,0) -> 0.34137106 | J22: =IFERROR(HistoricalFS!J44,0) -> 0.34632439 | ... L22: =IFERROR(HistoricalFS!L44,0) -> 0.29191038 | N22: =IFERROR(AVERAGE(C22:L22),0) -> 0.46356862 | O22: =IFERROR(MEDIAN(C22:L22),0) -> 0.40791092
B23: Return on Equity% | C23: =IFERROR(HistoricalFS!C33/SUM(HistoricalFS!C47:C48),0) -> 6.8773514 | D23: =IFERROR(HistoricalFS!D33/SUM(HistoricalFS!D47:D48),0) -> 0.22072255 | E23: =IFERROR(HistoricalFS!E33/SUM(HistoricalFS!E47:E48),0) -> 0.20940093 | F23: =IFERROR(HistoricalFS!F33/SUM(HistoricalFS!F47:F48),0) -> 0.20424051 | G23: =IFERROR(HistoricalFS!G33/SUM(HistoricalFS!G47:G48),0) -> 0.23929434 | H23: =IFERROR(HistoricalFS!H33/SUM(HistoricalFS!H47:H48),0) -> 0.22450686 | I23: =IFERROR(HistoricalFS!I33/SUM(HistoricalFS!I47:I48),0) -> 0.20192723 | J23: =IFERROR(HistoricalFS!J33/SUM(HistoricalFS!J47:J48),0) -> 0.23535617 | ... L23: =IFERROR(HistoricalFS!L33/SUM(HistoricalFS!L47:L48),0) -> 0.17317128 | N23: =IFERROR(AVERAGE(C23:L23),0) -> 0.88388896 | O23: =IFERROR(MEDIAN(C23:L23),0) -> 0.22261471
B24: Self Sustained Growth Rate | C24: =IFERROR(C22*C23,0) -> 6.7670955 | D24: =IFERROR(D22*D23,0) -> 0.090791687 | E24: =IFERROR(E22*E23,0) -> 0.11017654 | F24: =IFERROR(F22*F23,0) -> 0.097893998 | G24: =IFERROR(G22*G23,0) -> 0.12566929 | H24: =IFERROR(H22*H23,0) -> 0.090809282 | I24: =IFERROR(I22*I23,0) -> 0.068932112 | J24: =IFERROR(J22*J23,0) -> 0.081509583 | ... L24: =IFERROR(L22*L23,0) -> 0.050550495 | N24: =IFERROR(AVERAGE(C24:L24),0) -> 0.75657953 | O24: =IFERROR(MEDIAN(C24:L24),0) -> 0.090800484
B25: Interest Coverage Ratio | C25: =(HistoricalFS!C18-HistoricalFS!C24)/HistoricalFS!C21 -> 934.0198 | D25: =(HistoricalFS!D18-HistoricalFS!D24)/HistoricalFS!D21 -> 71.22877 | E25: =(HistoricalFS!E18-HistoricalFS!E24)/HistoricalFS!E21 -> 68.568604 | F25: =(HistoricalFS!F18-HistoricalFS!F24)/HistoricalFS!F21 -> 28.449353 | G25: =(HistoricalFS!G18-HistoricalFS!G24)/HistoricalFS!G21 -> 33.042803 | H25: =(HistoricalFS!H18-HistoricalFS!H24)/HistoricalFS!H21 -> 44.355888 | I25: =(HistoricalFS!I18-HistoricalFS!I24)/HistoricalFS!I21 -> 41.790693 | J25: =(HistoricalFS!J18-HistoricalFS!J24)/HistoricalFS!J21 -> 37.395777 | ... L25: =(HistoricalFS!L18-HistoricalFS!L24)/HistoricalFS!L21 -> 21.935821 | N25: =IFERROR(AVERAGE(C25:L25),0) -> 131.35992 | O25: =IFERROR(MEDIAN(C25:L25),0) -> 39.593235
B27: Debtor Turnover Ratio | C27: =HistoricalFS!C6/HistoricalFS!C59 -> 48.522969 | D27: =HistoricalFS!D6/HistoricalFS!D59 -> 10.411994 | E27: =HistoricalFS!E6/HistoricalFS!E59 -> 9.7216332 | F27: =HistoricalFS!F6/HistoricalFS!F59 -> 10.087468 | G27: =HistoricalFS!G6/HistoricalFS!G59 -> 11.258369 | H27: =HistoricalFS!H6/HistoricalFS!H59 -> 8.344109 | I27: =HistoricalFS!I6/HistoricalFS!I59 -> 7.5169136 | J27: =HistoricalFS!J6/HistoricalFS!J59 -> 7.4377909 | ... L27: =HistoricalFS!L6/HistoricalFS!L59 -> 7.8600767 | N27: =IFERROR(AVERAGE(C27:L27),0) -> 12.842137 | O27: =IFERROR(MEDIAN(C27:L27),0) -> 9.0328711
B28: Creditor Turnover Ratio | C28: =IFERROR(HistoricalFS!C6/HistoricalFS!C50,0) -> 15.518793 | D28: =IFERROR(HistoricalFS!D6/HistoricalFS!D50,0) -> 3.551552 | E28: =IFERROR(HistoricalFS!E6/HistoricalFS!E50,0) -> 3.4907009 | F28: =IFERROR(HistoricalFS!F6/HistoricalFS!F50,0) -> 3.524679 | G28: =IFERROR(HistoricalFS!G6/HistoricalFS!G50,0) -> 4.1337633 | H28: =IFERROR(HistoricalFS!H6/HistoricalFS!H50,0) -> 3.3632319 | I28: =IFERROR(HistoricalFS!I6/HistoricalFS!I50,0) -> 3.8493808 | J28: =IFERROR(HistoricalFS!J6/HistoricalFS!J50,0) -> 4.390945 | ... L28: =IFERROR(HistoricalFS!L6/HistoricalFS!L50,0) -> 3.9128717 | N28: =IFERROR(AVERAGE(C28:L28),0) -> 4.9816668 | O28: =IFERROR(MEDIAN(C28:L28),0) -> 3.8811262
B29: Inventory Turnover | C29: =IFERROR(HistoricalFS!C6/HistoricalFS!C60,0) -> 28.819861 | D29: =IFERROR(HistoricalFS!D6/HistoricalFS!D60,0) -> 5.7336635 | E29: =IFERROR(HistoricalFS!E6/HistoricalFS!E60,0) -> 6.3290399 | F29: =IFERROR(HistoricalFS!F6/HistoricalFS!F60,0) -> 6.1082493 | G29: =IFERROR(HistoricalFS!G6/HistoricalFS!G60,0) -> 5.9623548 | H29: =IFERROR(HistoricalFS!H6/HistoricalFS!H60,0) -> 5.715998 | I29: =IFERROR(HistoricalFS!I6/HistoricalFS!I60,0) -> 4.7296237 | J29: =IFERROR(HistoricalFS!J6/HistoricalFS!J60,0) -> 5.5531459 | ... L29: =IFERROR(HistoricalFS!L6/HistoricalFS!L60,0) -> 5.0460273 | N29: =IFERROR(AVERAGE(C29:L29),0) -> 7.9990244 | O29: =IFERROR(MEDIAN(C29:L29),0) -> 5.8480092
B30: Fixed Asset Turnover | C30: =IFERROR(HistoricalFS!C6/HistoricalFS!C53,0) -> 16.856879 | D30: =IFERROR(HistoricalFS!D6/HistoricalFS!D53,0) -> 4.5590724 | E30: =IFERROR(HistoricalFS!E6/HistoricalFS!E53,0) -> 4.5078961 | F30: =IFERROR(HistoricalFS!F6/HistoricalFS!F53,0) -> 2.9615874 | G30: =IFERROR(HistoricalFS!G6/HistoricalFS!G53,0) -> 3.2222977 | H30: =IFERROR(HistoricalFS!H6/HistoricalFS!H53,0) -> 3.7061903 | I30: =IFERROR(HistoricalFS!I6/HistoricalFS!I53,0) -> 5.2728689 | J30: =IFERROR(HistoricalFS!J6/HistoricalFS!J53,0) -> 5.9767488 | ... L30: =IFERROR(HistoricalFS!L6/HistoricalFS!L53,0) -> 3.6773592 | N30: =IFERROR(AVERAGE(C30:L30),0) -> 5.5707546 | O30: =IFERROR(MEDIAN(C30:L30),0) -> 4.5334843
B31: Capital Turnover Ratio | C31: =IFERROR(HistoricalFS!C6/SUM(HistoricalFS!C47:C48),0) -> 8.8261439 | D31: =IFERROR(HistoricalFS!D6/SUM(HistoricalFS!D47:D48),0) -> 1.9808269 | E31: =IFERROR(HistoricalFS!E6/SUM(HistoricalFS!E47:E48),0) -> 2.0004863 | F31: =IFERROR(HistoricalFS!F6/SUM(HistoricalFS!F47:F48),0) -> 2.0315747 | G31: =IFERROR(HistoricalFS!G6/SUM(HistoricalFS!G47:G48),0) -> 1.995156 | H31: =IFERROR(HistoricalFS!H6/SUM(HistoricalFS!H47:H48),0) -> 1.6954785 | I31: =IFERROR(HistoricalFS!I6/SUM(HistoricalFS!I47:I48),0) -> 2.1070234 | J31: =IFERROR(HistoricalFS!J6/SUM(HistoricalFS!J47:J48),0) -> 2.1565842 | ... L31: =IFERROR(HistoricalFS!L6/SUM(HistoricalFS!L47:L48),0) -> 1.7477295 | N31: =IFERROR(AVERAGE(C31:L31),0) -> 2.6436249 | O31: =IFERROR(MEDIAN(C31:L31),0) -> 1.9978212
B33: Debtor Days | C33: =IFERROR(365/C27,0) -> 7.5222108 | D33: =IFERROR(365/D27,0) -> 35.055726 | E33: =IFERROR(365/E27,0) -> 37.545132 | F33: =IFERROR(365/F27,0) -> 36.183511 | G33: =IFERROR(365/G27,0) -> 32.420325 | H33: =IFERROR(365/H27,0) -> 43.743436 | I33: =IFERROR(365/I27,0) -> 48.557163 | J33: =IFERROR(365/J27,0) -> 49.073711 | ... L33: =IFERROR(365/L27,0) -> 46.437206 | N33: =IFERROR(AVERAGE(C33:L33),0) -> 38.681358 | O33: =IFERROR(MEDIAN(C33:L33),0) -> 40.644284
B34: Payable Days | C34: =IFERROR(365/C28,0) -> 23.51987 | D34: =IFERROR(365/D28,0) -> 102.77197 | E34: =IFERROR(365/E28,0) -> 104.56353 | F34: =IFERROR(365/F28,0) -> 103.55553 | G34: =IFERROR(365/G28,0) -> 88.297268 | H34: =IFERROR(365/H28,0) -> 108.52656 | I34: =IFERROR(365/I28,0) -> 94.820446 | J34: =IFERROR(365/J28,0) -> 83.125613 | ... L34: =IFERROR(365/L28,0) -> 93.281873 | N34: =IFERROR(AVERAGE(C34:L34),0) -> 89.190701 | O34: =IFERROR(MEDIAN(C34:L34),0) -> 94.05116
B35: Inventory Days | C35: =IFERROR(365/C29,0) -> 12.664877 | D35: =IFERROR(365/D29,0) -> 63.659125 | E35: =IFERROR(365/E29,0) -> 57.670675 | F35: =IFERROR(365/F29,0) -> 59.755256 | G35: =IFERROR(365/G29,0) -> 61.217423 | H35: =IFERROR(365/H29,0) -> 63.855866 | I35: =IFERROR(365/I29,0) -> 77.173159 | J35: =IFERROR(365/J29,0) -> 65.728509 | ... L35: =IFERROR(365/L29,0) -> 72.334131 | N35: =IFERROR(AVERAGE(C35:L35),0) -> 59.497073 | O35: =IFERROR(MEDIAN(C35:L35),0) -> 62.438274
B36: Cash Conversion Cycle(in days) | C36: =SUM(C33,C35)-C34 -> -3.3327823 | D36: =SUM(D33,D35)-D34 -> -4.0571199 | E36: =SUM(E33,E35)-E34 -> -9.347721 | F36: =SUM(F33,F35)-F34 -> -7.6167625 | G36: =SUM(G33,G35)-G34 -> 5.3404812 | H36: =SUM(H33,H35)-H34 -> -0.92725992 | I36: =SUM(I33,I35)-I34 -> 30.909876 | J36: =SUM(J33,J35)-J34 -> 31.676607 | ... L36: =SUM(L33,L35)-L34 -> 25.489463 | N36: =IFERROR(AVERAGE(C36:L36),0) -> 8.9877306 | O36: =IFERROR(MEDIAN(C36:L36),0) -> 2.2066106
B38: CFO/Sales | C38: =IFERROR(HistoricalFS!C78/HistoricalFS!C6,0) -> 0.12493705 | D38: =IFERROR(HistoricalFS!D78/HistoricalFS!D6,0) -> 0.66007214 | E38: =IFERROR(HistoricalFS!E78/HistoricalFS!E6,0) -> 0.741476 | F38: =IFERROR(HistoricalFS!F78/HistoricalFS!F6,0) -> 0.75867471 | G38: =IFERROR(HistoricalFS!G78/HistoricalFS!G6,0) -> 0.26153751 | H38: =IFERROR(HistoricalFS!H78/HistoricalFS!H6,0) -> 0.042601619 | I38: =IFERROR(HistoricalFS!I78/HistoricalFS!I6,0) -> 0.45331339 | J38: =IFERROR(HistoricalFS!J78/HistoricalFS!J6,0) -> -0.028183234 | ... L38: =IFERROR(HistoricalFS!L78/HistoricalFS!L6,0) -> 0.54628112 | N38: =IFERROR(AVERAGE(C38:L38),0) -> 0.38319055 | O38: =IFERROR(MEDIAN(C38:L38),0) -> 0.36225429
B39: CFO/Total Assets | C39: =IFERROR(HistoricalFS!C78/HistoricalFS!C64,0) -> 0.68140729 | D39: =IFERROR(HistoricalFS!D78/HistoricalFS!D64,0) -> 0.80143875 | E39: =IFERROR(HistoricalFS!E78/HistoricalFS!E64,0) -> 0.90638414 | F39: =IFERROR(HistoricalFS!F78/HistoricalFS!F64,0) -> 0.89834105 | G39: =IFERROR(HistoricalFS!G78/HistoricalFS!G64,0) -> 0.32755049 | H39: =IFERROR(HistoricalFS!H78/HistoricalFS!H64,0) -> 0.045442621 | I39: =IFERROR(HistoricalFS!I78/HistoricalFS!I64,0) -> 0.57460375 | J39: =IFERROR(HistoricalFS!J78/HistoricalFS!J64,0) -> -0.037704626 | ... L39: =IFERROR(HistoricalFS!L78/HistoricalFS!L64,0) -> 0.61017452 | N39: =IFERROR(AVERAGE(C39:L39),0) -> 0.51295695 | O39: =IFERROR(MEDIAN(C39:L39),0) -> 0.59238913
B40: CFO/Total Debt | C40: =IFERROR(HistoricalFS!C78/HistoricalFS!C49,0) -> 22.25556 | D40: =IFERROR(HistoricalFS!D78/HistoricalFS!D49,0) -> 17.742799 | E40: =IFERROR(HistoricalFS!E78/HistoricalFS!E49,0) -> 23.386386 | F40: =IFERROR(HistoricalFS!F78/HistoricalFS!F49,0) -> 11.061685 | G40: =IFERROR(HistoricalFS!G78/HistoricalFS!G49,0) -> 4.7259723 | H40: =IFERROR(HistoricalFS!H78/HistoricalFS!H49,0) -> 0.8462017 | I40: =IFERROR(HistoricalFS!I78/HistoricalFS!I49,0) -> 8.313168 | J40: =IFERROR(HistoricalFS!J78/HistoricalFS!J49,0) -> -0.50294419 | ... L40: =IFERROR(HistoricalFS!L78/HistoricalFS!L49,0) -> 8.0871855 | N40: =IFERROR(AVERAGE(C40:L40),0) -> 9.9806281 | O40: =IFERROR(MEDIAN(C40:L40),0) -> 8.2001767

Sheet Cash Flow Data
C2: 42064 | D2: 42430 | E2: 42795 | F2: 43160 | G2: 43525 | H2: 43891 | I2: 44256 | J2: 44621 | K2: 44986 | L2: 45352 | M2: 45717
B3: Cash from Operating Activity - | C3: 4995 | D3: 6449 | E3: 8482 | F3: 10282 | G3: 11788 | H3: 6601 | I3: 3496 | J3: 8856 | K3: 1840 | L3: 9251 | M3: 16801
B4: Profit from operations | C4: 5111 | D4: 6779 | E4: 8935 | F4: 10413 | G4: 12036 | H4: 11060 | I4: 7503 | J4: 5531 | K4: 5832 | L4: 11112 | M4: 18676
B5: Receivables | C5: 46 | D5: 345 | E5: -204 | F5: 122 | G5: -262 | H5: -851 | I5: 340 | J5: 696 | K5: -764 | L5: -1258 | M5: -1316
B6: Inventory | C6: 124 | D6: -982 | E6: -450 | F6: -131 | G6: 104 | H6: -162 | I6: 109 | J6: 165 | K6: -483 | L6: -751 | M6: 125
B7: Payables | C7: 813 | D7: 712 | E7: 1789 | F7: 979 | G7: 2128 | H7: -858 | I7: -2155 | J7: 2680 | K7: -396 | L7: 2008 | M7: 3321
B8: Loans Advances | C8: -563 | D8: 23 | E8: -1 | F8: 1 | G8: 0 | H8: -13 | I8: -1 | J8: -6 | K8: -8 | L8: 1 | M8: -3
B9: Other WC items | C9: 321 | D9: 648 | E9: 325 | F9: 1222 | G9: 839 | H9: 569 | I9: -863 | J9: 801 | K9: -1162 | L9: 374 | M9: -406
B10: Working capital changes | C10: 742 | D10: 745 | E10: 1460 | F10: 2192 | G10: 2808 | H10: -1315 | I10: -2570 | J10: 4336 | K10: -2813 | L10: 373 | M10: 1722
B11: Direct taxes | C11: -858 | D11: -1075 | E11: -1912 | F11: -2323 | G11: -3056 | H11: -3144 | I11: -1438 | J11: -1011 | K11: -1178 | L11: -2233 | M11: -3597
B12: Cash from Investing Activity - | C12: -4997 | D12: -4491 | E12: -7230 | F12: -9173 | G12: -8302 | H12: -3540 | I12: -557 | J12: -7291 | K12: -239 | L12: -8036 | M12: -11865
B13: Fixed assets purchased | C13: -3545 | D13: -3058 | E13: -2469 | F13: -3391 | G13: -3912 | H13: -4872 | I13: -3437 | J13: -2370 | K13: -3459 | L13: -6347 | M13: -9200
B14: Fixed assets sold | C14: 9 | D14: 16 | E14: 12 | F14: 16 | G14: 26 | H14: 170 | I14: 37 | J14: 42 | K14: 136 | L14: 100 | M14: 45
... B29: Net Cash Flow | C29: -76 | D29: -45 | E29: 16 | F29: -20 | G29: 50 | H29: 113 | I29: -165 | J29: 20 | K29: -6 | L29: 2 | M29: 874

Sheet WACC
B2: Weighted Average Cost of Capital
B4: All figures are in INR unless stated otherwise
B6: Peer Comps
H7: Debt / | I7: Debt / | J7: Levered | K7: Unlevered
B8: Name of the Comp | D8: Country | E8: Total Debt | F8: Total Equity | G8: Tax Rate 1 | H8: Equity | I8: Capital | J8: Beta 2 | K8: Beta 3
B10: Avenue Super. | D10: India | E10: ='[1]Beta - Comps'!F3 -> 1609.19 | F10: ='[1]Beta - Comps'!E3 -> 287487.46 | G10: 0.3 | H10: =E10/F10 -> 0.0055974268 | I10: =E10/(E10+F10) -> 0.00556627 | J10: ='[1] Beta Regression'!N7 -> 1.2421196 | K10: =J10/(1+(1-G10)*H10) -> 1.2372718
B11: Vishal Mega Mart | D11: India | E11: ='[1]Beta - Comps'!F4 -> 1870.76 | F11: ='[1]Beta - Comps'!E4 -> 53854.19 | G11: 0.3 | H11: =E11/F11 -> 0.034737501 | I11: =E11/(E11+F11) -> 0.033571318 | J11: 0.976 | K11: =J11/(1+(1-G11)*H11) -> 0.95283073
B12: V-Mart Retail | D12: India | E12: ='[1]Beta - Comps'!F5 -> 801.24 | F12: ='[1]Beta - Comps'!E5 -> 4998.06 | G12: 0.3 | H12: =E12/F12 -> 0.1603102 | I12: =E12/(E12+F12) -> 0.1381615 | J12: 1.81 | K12: =J12/(1+(1-G12)*H12) -> 1.6273801
B13: Electronics Mart | D13: India | E13: ='[1]Beta - Comps'!F6 -> 1963.34 | F13: ='[1]Beta - Comps'!E6 -> 3818.73 | G13: 0.3 | H13: =E13/F13 -> 0.51413428 | I13: =E13/(E13+F13) -> 0.33955659 | J13: 1.87 | K13: =J13/(1+(1-G13)*H13) -> 1.3751072
B14: Shoppers Stop | D14: India | E14: ='[1]Beta - Comps'!F7 -> 3323.79 | F14: ='[1]Beta - Comps'!E7 -> 3279.84 | G14: 0.3 | H14: =E14/F14 -> 1.0134 | I14: =E14/(E14+F14) -> 0.50332772 | J14: 1.28 | K14: =J14/(1+(1-G14)*H14) -> 0.7488095
F16: Average | G16: =AVERAGE(G10:G14) -> 0.3 | H16: =AVERAGE(H10:H14) -> 0.34563589 | I16: =AVERAGE(I10:I14) -> 0.20403668 | J16: =AVERAGE(J10:J14) -> 1.4356239 | K16: =AVERAGE(K10:K14) -> 1.1882798
F17: Median | G17: =MEDIAN(G10:G14) -> 0.3 | H17: =MEDIAN(H10:H14) -> 0.1603102 | I17: =MEDIAN(I10:I14) -> 0.1381615 | J17: =MEDIAN(J10:J14) -> 1.28 | K17: =MEDIAN(K10:K14) -> 1.2372718
B19: Cost of Debt | G19: Cost of Equity
B21: Pre-Tax Cost of Debt | E21: =54/1609 -> 0.033561218 | G21: Risk Free Rate | K21: 0.0711
B22: Tax Rate | E22: =G17 -> 0.3 | G22: Equity Risk Premium | K22: =[1]Rm!F8-[1]WACC!K21 -> 0.080392308
B23: After Tax Cost of Debt | E23: =E21*(1-E22) -> 0.023492853 | G23: Levered Beta 4 | K23: =K32 -> 1.4592847
G24: Cost of Equity | K24: =K21+(K22*K23) -> 0.18841527
G27: Levered Beta
B28: Capital Structure
G29: Comps Median Unlevered Beta | K29: =K17 -> 1.2372718
D30: Current | E30: Target | G30: Target Debt / Equity | K30: =E35 -> 0.2563393
B31: Total Debt | C31: =E10 -> 1609.19 | D31: =C31/$C$33 -> 0.00556627 | E31: =I16 -> 0.20403668 | G31: Tax Rate | K31: =E22 -> 0.3
B32: Market Capitalization | C32: =F10 -> 287487.46 | D32: =C32/$C$33 -> 0.99443373 | E32: =E33-E31 -> 0.79596332 | G32: Levered Beta | K32: =K29*(1+(1-K31)*K30) -> 1.4592847
B33: Total Capitalization | C33: =SUM(C31:C32) -> 289096.65 | D33: =C33/$C$33 -> 1 | E33: =D33 -> 1
G34: Weighted Average Cost of Capital
B35: Debt / Equity | D35: =D31/D32 -> 0.0055974268 | E35: =E31/E32 -> 0.2563393
G36: Cost of Equity | K36: =K24 -> 0.18841527
B37: Notes: | G37: Equity Weight | K37: =E32 -> 0.79596332
B38: 1. Tax Rate considered as Marginal Tax Rate for the Country
B39: 2. Levered beta is based on 5 year monthly data | G39: Cost of Debt | K39: =E23 -> 0.023492853
B40: 3. Unlevered beta = Levered beta/(1+(1-Tax Rate)*Debt/Equity) | G40: Debt Weight | K40: =E31 -> 0.20403668
B41: 4. Levered beta = Unlevered beta*(1+(1-Tax Rate)*Debt/Equity)
G42: WACC | K42: =(K36*K37)+(K39*K40) -> 0.15476504

Sheet Forecasting
B2: ='Data Sheet'!B1&" - "&'Data Sheet'!A17&" Forecasting" -> ASIAN PAINTS LTD - Sales Forecasting | G2: ='Data Sheet'!$B$1&" - "&HistoricalFS!B18&" Forecasting" -> ASIAN PAINTS LTD - EBITDA Forecasting | L2: ='Data Sheet'!$B$1&" - "&HistoricalFS!B38&" Forecasting" -> ASIAN PAINTS LTD - Earning Per Share Forecasting
B3: Year Weight | C3: Year | D3: Sales | E3: Sales Growth | G3: Year Weight | H3: Year | I3: Sales | J3: Sales Growth | L3: Year Weight | M3: Year | N3: Sales | O3: Sales Growth
B4: 1 | C4: ='Data Sheet'!$B$16 -> 42460 | D4: {=TRANSPOSE('Data Sheet'!B17:K17)} -> 14271.49 | G4: 1 | H4: ='Data Sheet'!$B$16 -> 42460 | I4: {=TRANSPOSE('Data Sheet'!B51:K51)} -> 1924.95 | L4: 1 | M4: ='Data Sheet'!$B$16 -> 42460 | N4: {=TRANSPOSE(HistoricalFS!C38:L38)} -> 467.82193
B5: =B4+1 -> 2 | C5: =C4+365 -> 42825 | D5: 68085 | E5: =D5/D4-1 -> 3.7707002 | G5: =G4+1 -> 2 | H5: =H4+365 -> 42825 | I5: 5741.5 | J5: =I5/I4-1 -> 1.9826749 | L5: =L4+1 -> 2 | M5: =M4+365 -> 42825 | N5: 17.497394 | O5: =N5/N4-1 -> -0.96259818
B6: =B5+1 -> 3 | C6: =C5+365 -> 43190 | D6: 79809.4 | E6: =D6/D5-1 -> 0.17220239 | G6: =G5+1 -> 3 | H6: =H5+365 -> 43190 | I6: 6519.4 | J6: =I6/I5-1 -> 0.13548724 | L6: =L5+1 -> 3 | M6: =M5+365 -> 43190 | N6: 18.360196 | O6: =N6/N5-1 -> 0.049310335
B7: =B6+1 -> 4 | C7: =C6+365 -> 43555 | D7: 86068.5 | E7: =D7/D6-1 -> 0.078425599 | G7: =G6+1 -> 4 | H7: =H6+365 -> 43555 | I7: 6438.3 | J7: =I7/I6-1 -> -0.012439795 | L7: =L6+1 -> 4 | M7: =M6+365 -> 43555 | N7: 20.16545 | O7: =N7/N6-1 -> 0.098324352
B8: =B7+1 -> 5 | C8: =C7+365 -> 43920 | D8: 75660 | E8: =D8/D7-1 -> -0.12093275 | G8: =G7+1 -> 5 | H8: =H7+365 -> 43920 | I8: 6384.5 | J8: =I8/I7-1 -> -0.0083562431 | L8: =L7+1 -> 5 | M8: =M7+365 -> 43920 | N8: 25.271997 | O8: =N8/N7-1 -> 0.25323249
B9: =B8+1 -> 6 | C9: =C8+365 -> 44285 | D9: 70372 | E9: =D9/D8-1 -> -0.06989162 | G9: =G8+1 -> 6 | H9: =H8+365 -> 44285 | I9: 6505.5 | J9: =I9/I8-1 -> 0.01895215 | L9: =L8+1 -> 6 | M9: =M8+365 -> 44285 | N9: 29.973937 | O9: =N9/N8-1 -> 0.18605332
B10: =B9+1 -> 7 | C10: =C9+365 -> 44650 | D10: 88329.8 | E10: =D10/D9-1 -> 0.25518388 | G10: =G9+1 -> 7 | H10: =H9+365 -> 44650 | I10: 6305.8 | J10: =I10/I9-1 -> -0.030697102 | L10: =L9+1 -> 7 | M10: =M9+365 -> 44650 | N10: 29.075584 | O10: =N10/N9-1 -> -0.029971131
B11: =B10+1 -> 8 | C11: =C10+365 -> 45015 | D11: 117571.3 | E11: =D11/D10-1 -> 0.33104909 | G11: =G10+1 -> 8 | H11: =H10+365 -> 45015 | I11: 6178.6 | J11: =I11/I10-1 -> -0.020171905 | L11: =L10+1 -> 8 | M11: =M10+365 -> 45015 | N11: 39.239679 | O11: =N11/N10-1 -> 0.34957493
B12: =B11+1 -> 9 | C12: =C11+365 -> 45380 | D12: 141858.2 | E12: =D12/D11-1 -> 0.20657167 | G12: =G11+1 -> 9 | H12: =H11+365 -> 45380 | I12: 6789 | J12: =I12/I11-1 -> 0.098792607 | L12: =L11+1 -> 9 | M12: =M11+365 -> 45380 | N12: 49.382089 | O12: =N12/N11-1 -> 0.25847333
B13: =B12+1 -> 10 | C13: =C12+365 -> 45745 | D13: 152913 | E13: =D13/D12-1 -> 0.077928523 | G13: =G12+1 -> 10 | H13: =H12+365 -> 45745 | I13: 7307.7 | J13: =I13/I12-1 -> 0.076403005 | L13: =L12+1 -> 10 | M13: =M12+365 -> 45745 | N13: 35.023874 | O13: =N13/N12-1 -> -0.29075755
B14: =B13+1 -> 11 | C14: =C13+365 -> 46110 | D14: =FORECAST(B14,$D$4:$D$13,$B$4:$B$13) -> 154643.58 | E14: =D14/D13-1 -> 0.011317429 | G14: =G13+1 -> 11 | H14: =H13+365 -> 46110 | I14: =FORECAST(G14,$I$4:$I$13,$G$4:$G$13) -> 7802.75 | J14: =I14/I13-1 -> 0.067743613 | L14: =L13+1 -> 11 | M14: =M13+365 -> 46110 | N14: =FORECAST(L14,$N$4:$N$13,$L$4:$L$13) -> -44.690784 | O14: =N14/N13-1 -> -2.2760092
B15: =B14+1 -> 12 | C15: =C14+365 -> 46475 | D15: =FORECAST(B15,$D$4:$D$13,$B$4:$B$13) -> 166488.98 | E15: =D15/D14-1 -> 0.076598086 | G15: =G14+1 -> 12 | H15: =H14+365 -> 46475 | I15: =FORECAST(G15,$I$4:$I$13,$G$4:$G$13) -> 8128.7909 | J15: =I15/I14-1 -> 0.041785385 | L15: =L14+1 -> 12 | M15: =M14+365 -> 46475 | N15: =FORECAST(L15,$N$4:$N$13,$L$4:$L$13) -> -66.122056 | O15: =N15/N14-1 -> 0.47954568
B16: =B15+1 -> 13 | C16: =C15+365 -> 46840 | D16: =FORECAST(B16,$D$4:$D$13,$B$4:$B$13) -> 178334.39 | E16: =D16/D15-1 -> 0.071148265 | G16: =G15+1 -> 13 | H16: =H15+365 -> 46840 | I16: =FORECAST(G16,$I$4:$I$13,$G$4:$G$13) -> 8454.8318 | J16: =I16/I15-1 -> 0.040109398 | L16: =L15+1 -> 13 | M16: =M15+365 -> 46840 | N16: =FORECAST(L16,$N$4:$N$13,$L$4:$L$13) -> -87.553329 | O16: =N16/N15-1 -> 0.32411685
B17: =B16+1 -> 14 | C17: =C16+365 -> 47205 | D17: =FORECAST(B17,$D$4:$D$13,$B$4:$B$13) -> 190179.79 | E17: =D17/D16-1 -> 0.066422425 | G17: =G16+1 -> 14 | H17: =H16+365 -> 47205 | I17: =FORECAST(G17,$I$4:$I$13,$G$4:$G$13) -> 8780.8727 | J17: =I17/I16-1 -> 0.038562672 | L17: =L16+1 -> 14 | M17: =M16+365 -> 47205 | N17: =FORECAST(L17,$N$4:$N$13,$L$4:$L$13) -> -108.9846 | O17: =N17/N16-1 -> 0.24477964
B18: =B17+1 -> 15 | C18: =C17+365 -> 47570 | D18: =FORECAST(B18,$D$4:$D$13,$B$4:$B$13) -> 202025.19 | E18: =D18/D17-1 -> 0.062285285 | G18: =G17+1 -> 15 | H18: =H17+365 -> 47570 | I18: =FORECAST(G18,$I$4:$I$13,$G$4:$G$13) -> 9106.9136 | J18: =I18/I17-1 -> 0.037130809 | L18: =L17+1 -> 15 | M18: =M17+365 -> 47570 | N18: =FORECAST(L18,$N$4:$N$13,$L$4:$L$13) -> -130.41587 | O18: =N18/N17-1 -> 0.19664496

Sheet HistoricalFS
B2: ="Historical Financial Statement- "&'Data Sheet'!B1 -> Historical Financial Statement- ASIAN PAINTS LTD
B3: Years | C3: ='Data Sheet'!B16 -> 42460 | D3: ='Data Sheet'!C16 -> 42825 | E3: ='Data Sheet'!D16 -> 43190 | F3: ='Data Sheet'!E16 -> 43555 | G3: ='Data Sheet'!F16 -> 43921 | H3: ='Data Sheet'!G16 -> 44286 | I3: ='Data Sheet'!H16 -> 44651 | J3: ='Data Sheet'!I16 -> 45016 | ... L3: ='Data Sheet'!K16 -> 45747 | M3: LTM
A5: # | B5: Income Statement
B6: Sales | C6: =IFERROR('[2]Data Sheet'!B17,0) -> 57589 | D6: =IFERROR('Data Sheet'!C17,0) -> 15061.99 | E6: =IFERROR('Data Sheet'!D17,0) -> 16824.55 | F6: =IFERROR('Data Sheet'!E17,0) -> 19240.13 | G6: =IFERROR('Data Sheet'!F17,0) -> 20211.25 | H6: =IFERROR('Data Sheet'!G17,0) -> 21712.79 | I6: =IFERROR('Data Sheet'!H17,0) -> 29101.28 | J6: =IFERROR('Data Sheet'!I17,0) -> 34488.59 | K6: =IFERROR('Data Sheet'!J17,0) -> 35494.73 | L6: =IFERROR('Data Sheet'!K17,0) -> 33905.62 | M6: =IFERROR(SUM('Data Sheet'!H42:K42),0) -> 34695.75
B7: Sales Growth | C7: - | D7: =D6/C6-1 -> -0.73845717 | E7: =E6/D6-1 -> 0.11702039 | F7: =F6/E6-1 -> 0.14357472 | G7: =G6/F6-1 -> 0.050473671 | H7: =H6/G6-1 -> 0.074292288 | I7: =I6/H6-1 -> 0.34028285 | J7: =J6/I6-1 -> 0.18512278 | K7: =K6/J6-1 -> 0.029173127 | ... M7: =M6/L6-1 -> 0.023303806
B9: COGS | C9: =IFERROR(SUM('Data Sheet'!B18,'Data Sheet'!B20:B22)-1*'Data Sheet'!B19,0) -> 9413.84 | D9: =IFERROR(SUM('Data Sheet'!C18,'Data Sheet'!C20:C22)-1*'Data Sheet'!C19,0) -> 9732.66 | E9: =IFERROR(SUM('Data Sheet'!D18,'Data Sheet'!D20:D22)-1*'Data Sheet'!D19,0) -> 11194.17 | F9: =IFERROR(SUM('Data Sheet'!E18,'Data Sheet'!E20:E22)-1*'Data Sheet'!E19,0) -> 12905.81 | G9: =IFERROR(SUM('Data Sheet'!F18,'Data Sheet'!F20:F22)-1*'Data Sheet'!F19,0) -> 13158.02 | H9: =IFERROR(SUM('Data Sheet'!G18,'Data Sheet'!G20:G22)-1*'Data Sheet'!G19,0) -> 14035.07 | I9: =IFERROR(SUM('Data Sheet'!H18,'Data Sheet'!H20:H22)-1*'Data Sheet'!H19,0) -> 20590.57 | J9: =IFERROR(SUM('Data Sheet'!I18,'Data Sheet'!I20:I22)-1*'Data Sheet'!I19,0) -> 23766.7 | ... L9: =IFERROR(SUM('Data Sheet'!K18,'Data Sheet'!K20:K22)-1*'Data Sheet'!K19,0) -> 22741.27 | M9: =IFERROR(SUM('Data Sheet'!H43:K43),0) -> 28350.24
B10: COGS % Sales | C10: =C9/C6 -> 0.16346594 | D10: =D9/D6 -> 0.64617358 | E10: =E9/E6 -> 0.66534736 | F10: =F9/F6 -> 0.67077561 | G10: =G9/G6 -> 0.65102455 | H10: =H9/H6 -> 0.64639643 | I10: =I9/I6 -> 0.7075486 | J10: =J9/J6 -> 0.68911776 | ... M10: =M9/M6 -> 0.81710988
B12: Gross Profit | C12: =C6-C9 -> 48175.16 | D12: =D6-D9 -> 5329.33 | E12: =E6-E9 -> 5630.38 | F12: =F6-F9 -> 6334.32 | G12: =G6-G9 -> 7053.23 | H12: =H6-H9 -> 7677.72 | I12: =I6-I9 -> 8510.71 | J12: =J6-J9 -> 10721.89 | ... M12: =M6-M9 -> 6345.51
B13: Gross Margins | C13: =C12/C6 -> 0.83653406 | D13: =D12/D6 -> 0.35382642 | E13: =E12/E6 -> 0.33465264 | F13: =F12/F6 -> 0.32922439 | G13: =G12/G6 -> 0.34897545 | H13: =H12/H6 -> 0.35360357 | I13: =I12/I6 -> 0.2924514 | J13: =J12/J6 -> 0.31088224 | ... M13: =M12/M6 -> 0.18289012
B15: Selling & General Expenses | C15: =IFERROR(SUM('Data Sheet'!B23:B24),0) -> 2132.61 | D15: =IFERROR(SUM('Data Sheet'!C23:C24),0) -> 2335.57 | E15: =IFERROR(SUM('Data Sheet'!D23:D24),0) -> 2426.37 | F15: =IFERROR(SUM('Data Sheet'!E23:E24),0) -> 2569.38 | G15: =IFERROR(SUM('Data Sheet'!F23:F24),0) -> 2891.46 | H15: =IFERROR(SUM('Data Sheet'!G23:G24),0) -> 2822.12 | I15: =IFERROR(SUM('Data Sheet'!H23:H24),0) -> 3707.1 | J15: =IFERROR(SUM('Data Sheet'!I23:I24),0) -> 4462.05 | ... M15: =IFERROR(SUM('Data Sheet'!L23:L24),0) -> 0
B16: S&G Exp % Sales | C16: =C15/C6 -> 0.037031551 | D16: =D15/D6 -> 0.15506384 | E16: =E15/E6 -> 0.14421604 | F16: =F15/F6 -> 0.13354276 | G16: =G15/G6 -> 0.14306191 | H16: =H15/H6 -> 0.12997501 | I16: =I15/I6 -> 0.12738615 | J16: =J15/J6 -> 0.12937757 | ... M16: =M15/M6 -> 0
B18: EBITDA | C18: =C12-C15 -> 46042.55 | D18: =D12-D15 -> 2993.76 | E18: =E12-E15 -> 3204.01 | F18: =F12-F15 -> 3764.94 | G18: =G12-G15 -> 4161.77 | H18: =H12-H15 -> 4855.6 | I18: =I12-I15 -> 4803.61 | J18: =J12-J15 -> 6259.84 | ... L18: =L12-L15 -> 6006.21 | M18: =IFERROR(SUM('Data Sheet'!H51:K51),0) -> 7565.48
B19: EBITDA Margins | C19: =C18/C6 -> 0.79950251 | D19: =D18/D6 -> 0.19876258 | E19: =E18/E6 -> 0.19043659 | F19: =F18/F6 -> 0.19568163 | G19: =G18/G6 -> 0.20591354 | H19: =H18/H6 -> 0.22362856 | I19: =I18/I6 -> 0.16506525 | J19: =J18/J6 -> 0.18150467 | ... M19: =M18/M6 -> 0.21805207
B21: Interest | C21: =IFERROR('Data Sheet'!B27,0) -> 49 | D21: =IFERROR('Data Sheet'!C27,0) -> 37.33 | E21: =IFERROR('Data Sheet'!D27,0) -> 41.47 | F21: =IFERROR('Data Sheet'!E27,0) -> 110.47 | G21: =IFERROR('Data Sheet'!F27,0) -> 102.33 | H21: =IFERROR('Data Sheet'!G27,0) -> 91.63 | I21: =IFERROR('Data Sheet'!H27,0) -> 95.41 | J21: =IFERROR('Data Sheet'!I27,0) -> 144.45 | ... L21: =IFERROR('Data Sheet'!K27,0) -> 227.02 | M21: =IFERROR(SUM('Data Sheet'!H46:K46),0) -> 189.1
B22: Interest % Sales | C22: =C21/C6 -> 0.00085085693 | D22: =D21/D6 -> 0.0024784242 | E22: =E21/E6 -> 0.0024648505 | F22: =F21/F6 -> 0.0057416452 | G22: =G21/G6 -> 0.0050630218 | H22: =H21/H6 -> 0.0042200933 | I22: =I21/I6 -> 0.0032785499 | J22: =J21/J6 -> 0.0041883417 | ... M22: =M21/M6 -> 0.0054502353
B24: Depreciation | C24: =IFERROR('Data Sheet'!B26,0) -> 275.58 | D24: =IFERROR('Data Sheet'!C26,0) -> 334.79 | E24: =IFERROR('Data Sheet'!D26,0) -> 360.47 | F24: =IFERROR('Data Sheet'!E26,0) -> 622.14 | G24: =IFERROR('Data Sheet'!F26,0) -> 780.5 | H24: =IFERROR('Data Sheet'!G26,0) -> 791.27 | I24: =IFERROR('Data Sheet'!H26,0) -> 816.36 | J24: =IFERROR('Data Sheet'!I26,0) -> 858.02 | ... L24: =IFERROR('Data Sheet'!K26,0) -> 1026.34 | M24: =IFERROR(SUM('Data Sheet'!H45:K45),0) -> 1219.97
B25: Depreciation %Sales | C25: =C24/C6 -> 0.0047852889 | D25: =D24/D6 -> 0.022227475 | E25: =E24/E6 -> 0.021425239 | F25: =F24/F6 -> 0.03233554 | G25: =G24/G6 -> 0.038617107 | H25: =H24/H6 -> 0.036442576 | I25: =I24/I6 -> 0.028052374 | J25: =J24/J6 -> 0.024878373 | ... M25: =M24/M6 -> 0.035161943
B27: Earning Before Tax | C27: =IFERROR(C18-SUM(C24,C21),0) -> 45717.97 | D27: =IFERROR(D18-SUM(D24,D21),0) -> 2621.64 | E27: =IFERROR(E18-SUM(E24,E21),0) -> 2802.07 | F27: =IFERROR(F18-SUM(F24,F21),0) -> 3032.33 | G27: =IFERROR(G18-SUM(G24,G21),0) -> 3278.94 | H27: =IFERROR(H18-SUM(H24,H21),0) -> 3972.7 | I27: =IFERROR(I18-SUM(I24,I21),0) -> 3891.84 | J27: =IFERROR(J18-SUM(J24,J21),0) -> 5257.37 | ... M27: =IFERROR(M18-SUM(M24,M21),0) -> 6156.41
B28: EBT % Sales | C28: =C27/C6 -> 0.79386636 | D28: =D27/D6 -> 0.17405668 | E28: =E27/E6 -> 0.1665465 | F28: =F27/F6 -> 0.15760444 | G28: =G27/G6 -> 0.16223341 | H28: =H27/H6 -> 0.18296589 | I28: =I27/I6 -> 0.13373432 | J28: =J27/J6 -> 0.15243795 | ... M28: =M27/M6 -> 0.17743989
B30: Tax | C30: =IFERROR('Data Sheet'!B29,0) -> 844.49 | D30: =IFERROR('Data Sheet'!C29,0) -> 943.29 | E30: =IFERROR('Data Sheet'!D29,0) -> 1040.96 | F30: =IFERROR('Data Sheet'!E29,0) -> 1098.06 | G30: =IFERROR('Data Sheet'!F29,0) -> 854.85 | H30: =IFERROR('Data Sheet'!G29,0) -> 1097.6 | I30: =IFERROR('Data Sheet'!H29,0) -> 1102.91 | J30: =IFERROR('Data Sheet'!I29,0) -> 1493.5 | ... L30: =IFERROR('Data Sheet'!K29,0) -> 1393.36 | M30: =IFERROR(SUM('Data Sheet'!H48:K48),0) -> 1501.54
B31: Effective Tax Rate | C31: =C30/C27 -> 0.01847173 | D31: =D30/D27 -> 0.35980913 | E31: =E30/E27 -> 0.37149679 | F31: =F30/F27 -> 0.36211758 | G31: =G30/G27 -> 0.26070925 | H31: =H30/H27 -> 0.27628565 | I31: =I30/I27 -> 0.28339038 | J31: =J30/J27 -> 0.2840774 | ... M31: =M30/M27 -> 0.24389864
B33: Net Profit | C33: =IFERROR(C27-C30,0) -> 44873.48 | D33: =IFERROR(D27-D30,0) -> 1678.35 | E33: =IFERROR(E27-E30,0) -> 1761.11 | F33: =IFERROR(F27-F30,0) -> 1934.27 | G33: =IFERROR(G27-G30,0) -> 2424.09 | H33: =IFERROR(H27-H30,0) -> 2875.1 | I33: =IFERROR(I27-I30,0) -> 2788.93 | J33: =IFERROR(J27-J30,0) -> 3763.87 | ... M33: =IFERROR(M27-M30,0) -> 4654.87
B34: Net Margins | C34: =C33/C6 -> 0.77920228 | D34: =D33/D6 -> 0.1114295 | E34: =E33/E6 -> 0.10467501 | F34: =F33/F6 -> 0.1005331 | G34: =G33/G6 -> 0.11993766 | H34: =H33/H6 -> 0.13241504 | I34: =I33/I6 -> 0.095835303 | J34: =J33/J6 -> 0.10913377 | ... M34: =M33/M6 -> 0.13416254
B36: No. of Equity Shares | C36: =IFERROR('Data Sheet'!B93,0) -> 95.92 | D36: =IFERROR('Data Sheet'!C93,0) -> 95.92 | E36: =IFERROR('Data Sheet'!D93,0) -> 95.92 | F36: =IFERROR('Data Sheet'!E93,0) -> 95.92 | G36: =IFERROR('Data Sheet'!F93,0) -> 95.92 | H36: =IFERROR('Data Sheet'!G93,0) -> 95.92 | I36: =IFERROR('Data Sheet'!H93,0) -> 95.92 | J36: =IFERROR('Data Sheet'!I93,0) -> 95.92 | ... M36: =IFERROR('Data Sheet'!L93,0) -> 0
B38: Earning Per Share | C38: =IFERROR(C33/C36,0) -> 467.82193 | D38: =IFERROR(D33/D36,0) -> 17.497394 | E38: =IFERROR(E33/E36,0) -> 18.360196 | F38: =IFERROR(F33/F36,0) -> 20.16545 | G38: =IFERROR(G33/G36,0) -> 25.271997 | H38: =IFERROR(H33/H36,0) -> 29.973937 | I38: =IFERROR(I33/I36,0) -> 29.075584 | J38: =IFERROR(J33/J36,0) -> 39.239679 | ... M38: =IFERROR(M33/M36,0) -> 0
B39: EPS Growth % | D39: =IFERROR(D38/C38-1,0) -> -0.96259818 | E39: =IFERROR(E38/D38-1,0) -> 0.049310335 | F39: =IFERROR(F38/E38-1,0) -> 0.098324352 | G39: =IFERROR(G38/F38-1,0) -> 0.25323249 | H39: =IFERROR(H38/G38-1,0) -> 0.18605332 | I39: =IFERROR(I38/H38-1,0) -> -0.029971131 | J39: =IFERROR(J38/I38-1,0) -> 0.34957493 | K39: =IFERROR(K38/J38-1,0) -> 0.25847333 | ... M39: =IFERROR(M38/L38-1,0) -> -1
B41: Dividend Per Share | C41: =IFERROR('Data Sheet'!B31/HistoricalFS!C36,0) -> 7.5 | D41: =IFERROR('Data Sheet'!C31/HistoricalFS!D36,0) -> 10.300042 | E41: =IFERROR('Data Sheet'!D31/HistoricalFS!E36,0) -> 8.6999583 | F41: =IFERROR('Data Sheet'!E31/HistoricalFS!F36,0) -> 10.5 | G41: =IFERROR('Data Sheet'!F31/HistoricalFS!G36,0) -> 12 | H41: =IFERROR('Data Sheet'!G31/HistoricalFS!H36,0) -> 17.849979 | I41: =IFERROR('Data Sheet'!H31/HistoricalFS!I36,0) -> 19.150021 | J41: =IFERROR('Data Sheet'!I31/HistoricalFS!J36,0) -> 25.650021 | ... M41: =IFERROR('Data Sheet'!L31/HistoricalFS!M36,0) -> 0
B42: Dividend Payout Ratio | C42: =IFERROR(C41/C38,0) -> 0.016031741 | D42: =IFERROR(D41/D38,0) -> 0.58866148 | E42: =IFERROR(E41/E38,0) -> 0.47384888 | F42: =IFERROR(F41/F38,0) -> 0.52069256 | G42: =IFERROR(G41/G38,0) -> 0.47483386 | H42: =IFERROR(H41/H38,0) -> 0.59551668 | I42: =IFERROR(I41/I38,0) -> 0.65862894 | J42: =IFERROR(J41/J38,0) -> 0.65367561 | ... M42: =IFERROR(M41/M38,0) -> 0
B44: Retained Earnings | C44: =IFERROR(IF(C38>C41,1-C42,0),0) -> 0.98396826 | D44: =IFERROR(IF(D38>D41,1-D42,0),0) -> 0.41133852 | E44: =IFERROR(IF(E38>E41,1-E42,0),0) -> 0.52615112 | F44: =IFERROR(IF(F38>F41,1-F42,0),0) -> 0.47930744 | G44: =IFERROR(IF(G38>G41,1-G42,0),0) -> 0.52516614 | H44: =IFERROR(IF(H38>H41,1-H42,0),0) -> 0.40448332 | I44: =IFERROR(IF(I38>I41,1-I42,0),0) -> 0.34137106 | J44: =IFERROR(IF(J38>J41,1-J42,0),0) -> 0.34632439 | ... M44: =IFERROR(IF(M38>M41,1-M42,0),0) -> 0
A46: # | B46: Balance Sheet
B47: Equity Share Capital | C47: =IFERROR('Data Sheet'!B57,0) -> 95.92 | D47: =IFERROR('Data Sheet'!C57,0) -> 95.92 | E47: =IFERROR('Data Sheet'!D57,0) -> 95.92 | F47: =IFERROR('Data Sheet'!E57,0) -> 95.92 | G47: =IFERROR('Data Sheet'!F57,0) -> 95.92 | H47: =IFERROR('Data Sheet'!G57,0) -> 95.92 | I47: =IFERROR('Data Sheet'!H57,0) -> 95.92 | J47: =IFERROR('Data Sheet'!I57,0) -> 95.92 | ... L47: =IFERROR('Data Sheet'!K57,0) -> 95.92
B48: Reserves | C48: =IFERROR('Data Sheet'!B58,0) -> 6428.9 | D48: =IFERROR('Data Sheet'!C58,0) -> 7507.97 | E48: =IFERROR('Data Sheet'!D58,0) -> 8314.31 | F48: =IFERROR('Data Sheet'!E58,0) -> 9374.63 | G48: =IFERROR('Data Sheet'!F58,0) -> 10034.24 | H48: =IFERROR('Data Sheet'!G58,0) -> 12710.37 | I48: =IFERROR('Data Sheet'!H58,0) -> 13715.64 | J48: =IFERROR('Data Sheet'!I58,0) -> 15896.31 | ... L48: =IFERROR('Data Sheet'!K58,0) -> 19303.89
B49: Borrowings | C49: =IFERROR('Data Sheet'!B59,0) -> 323.29 | D49: =IFERROR('Data Sheet'!C59,0) -> 560.34 | E49: =IFERROR('Data Sheet'!D59,0) -> 533.43 | F49: =IFERROR('Data Sheet'!E59,0) -> 1319.6 | G49: =IFERROR('Data Sheet'!F59,0) -> 1118.5 | H49: =IFERROR('Data Sheet'!G59,0) -> 1093.12 | I49: =IFERROR('Data Sheet'!H59,0) -> 1586.88 | J49: =IFERROR('Data Sheet'!I59,0) -> 1932.62 | ... L49: =IFERROR('Data Sheet'!K59,0) -> 2290.29
B50: Other Liabilities | C50: =IFERROR('Data Sheet'!B60,0) -> 3710.92 | D50: =IFERROR('Data Sheet'!C60,0) -> 4240.96 | E50: =IFERROR('Data Sheet'!D60,0) -> 4819.82 | F50: =IFERROR('Data Sheet'!E60,0) -> 5458.69 | G50: =IFERROR('Data Sheet'!F60,0) -> 4889.31 | H50: =IFERROR('Data Sheet'!G60,0) -> 6455.93 | I50: =IFERROR('Data Sheet'!H60,0) -> 7559.99 | J50: =IFERROR('Data Sheet'!I60,0) -> 7854.48 | ... L50: =IFERROR('Data Sheet'!K60,0) -> 8665.15
B51: Total Liabilities | C51: =IFERROR('Data Sheet'!B61,0) -> 10559.03 | D51: =IFERROR('Data Sheet'!C61,0) -> 12405.19 | E51: =IFERROR('Data Sheet'!D61,0) -> 13763.48 | F51: =IFERROR('Data Sheet'!E61,0) -> 16248.84 | G51: =IFERROR('Data Sheet'!F61,0) -> 16137.97 | H51: =IFERROR('Data Sheet'!G61,0) -> 20355.34 | I51: =IFERROR('Data Sheet'!H61,0) -> 22958.43 | J51: =IFERROR('Data Sheet'!I61,0) -> 25779.33 | ... L51: =IFERROR('Data Sheet'!K61,0) -> 30355.25
B53: Fixed Assets Net Block | C53: =IFERROR('Data Sheet'!B62,0) -> 3416.35 | D53: =IFERROR('Data Sheet'!C62,0) -> 3303.74 | E53: =IFERROR('Data Sheet'!D62,0) -> 3732.24 | F53: =IFERROR('Data Sheet'!E62,0) -> 6496.56 | G53: =IFERROR('Data Sheet'!F62,0) -> 6272.31 | H53: =IFERROR('Data Sheet'!G62,0) -> 5858.52 | I53: =IFERROR('Data Sheet'!H62,0) -> 5519.06 | J53: =IFERROR('Data Sheet'!I62,0) -> 5770.46 | ... L53: =IFERROR('Data Sheet'!K62,0) -> 9220.1
B54: Capital Work in Progress | C54: =IFERROR('Data Sheet'!B63,0) -> 106.59 | D54: =IFERROR('Data Sheet'!C63,0) -> 257.54 | E54: =IFERROR('Data Sheet'!D63,0) -> 1405.11 | F54: =IFERROR('Data Sheet'!E63,0) -> 209.67 | G54: =IFERROR('Data Sheet'!F63,0) -> 140.24 | H54: =IFERROR('Data Sheet'!G63,0) -> 182.98 | I54: =IFERROR('Data Sheet'!H63,0) -> 426.43 | J54: =IFERROR('Data Sheet'!I63,0) -> 1019.59 | ... L54: =IFERROR('Data Sheet'!K63,0) -> 1254.49
B55: Investments | C55: =IFERROR('Data Sheet'!B64,0) -> 2712.13 | D55: =IFERROR('Data Sheet'!C64,0) -> 2651.99 | E55: =IFERROR('Data Sheet'!D64,0) -> 2140.7 | F55: =IFERROR('Data Sheet'!E64,0) -> 2568.58 | G55: =IFERROR('Data Sheet'!F64,0) -> 2018.85 | H55: =IFERROR('Data Sheet'!G64,0) -> 4736.8 | I55: =IFERROR('Data Sheet'!H64,0) -> 3247.53 | J55: =IFERROR('Data Sheet'!I64,0) -> 4261.71 | ... L55: =IFERROR('Data Sheet'!K64,0) -> 4724.75
B56: Other Assets | C56: =IFERROR('Data Sheet'!B65-SUM('Data Sheet'!B67:B69),0) -> 714.68 | D56: =IFERROR('Data Sheet'!C65-SUM('Data Sheet'!C67:C69),0) -> 1317.17 | E56: =IFERROR('Data Sheet'!D65-SUM('Data Sheet'!D67:D69),0) -> 1691.84 | F56: =IFERROR('Data Sheet'!E65-SUM('Data Sheet'!E67:E69),0) -> 1471.96 | G56: =IFERROR('Data Sheet'!F65-SUM('Data Sheet'!F67:F69),0) -> 1738.71 | H56: =IFERROR('Data Sheet'!G65-SUM('Data Sheet'!G67:G69),0) -> 2565.52 | I56: =IFERROR('Data Sheet'!H65-SUM('Data Sheet'!H67:H69),0) -> 2876.66 | J56: =IFERROR('Data Sheet'!I65-SUM('Data Sheet'!I67:I69),0) -> 3036.17 | ... L56: =IFERROR('Data Sheet'!K65-SUM('Data Sheet'!K67:K69),0) -> 3341.01
B57: Total Non Current Assets | C57: =SUM(C53:C56) -> 6949.75 | D57: =SUM(D53:D56) -> 7530.44 | E57: =SUM(E53:E56) -> 8969.89 | F57: =SUM(F53:F56) -> 10746.77 | G57: =SUM(G53:G56) -> 10170.11 | H57: =SUM(H53:H56) -> 13343.82 | I57: =SUM(I53:I56) -> 12069.68 | J57: =SUM(J53:J56) -> 14087.93 | ... L57: =SUM(L53:L56) -> 18540.35
...

Sheet Intrisic Growth
B2: Calculation of ROIC | G2: ='[1]Raw FS'!J2 -> 44256 | H2: ='[1]Raw FS'!K2 -> 44621 | I2: ='[1]Raw FS'!L2 -> 44986 | J2: ='[1]Raw FS'!M2 -> 45352 | K2: ='[1]Raw FS'!N2 -> 45717
B4: Current Assets
B5: Inventories | G5: ='Raw FS'!J35 -> 3799 | H5: ='Raw FS'!K35 -> 6153 | I5: ='Raw FS'!L35 -> 6211 | J5: ='Raw FS'!M35 -> 5923 | K5: ='Raw FS'!N35 -> 6719
B6: Trade receivables | G6: ='Raw FS'!J36 -> 2602 | H6: ='Raw FS'!K36 -> 3871 | I6: ='Raw FS'!L36 -> 4637 | J6: ='Raw FS'!M36 -> 4889 | K6: ='Raw FS'!N36 -> 4314
B7: Loans n Advances | G7: ='Raw FS'!J38 -> 12 | H7: ='Raw FS'!K38 -> 8 | I7: ='Raw FS'!L38 -> 12 | J7: ='Raw FS'!M38 -> 17 | K7: ='Raw FS'!N38 -> 22
B8: Other asset items | G8: ='Raw FS'!J39 -> 2554 | H8: ='Raw FS'!K39 -> 2869 | I8: ='Raw FS'!L39 -> 3024 | J8: ='Raw FS'!M39 -> 3555 | K8: ='Raw FS'!N39 -> 3319
B9: Total Current Assets | G9: =SUM(G5:G8) -> 8967 | H9: =SUM(H5:H8) -> 12901 | I9: =SUM(I5:I8) -> 13884 | J9: =SUM(J5:J8) -> 14384 | K9: =SUM(K5:K8) -> 14374
B11: Current Liabilities
B12: Trade Payables | G12: ='Raw FS'!J13 -> 3379 | H12: ='Raw FS'!K13 -> 4164 | I12: ='Raw FS'!L13 -> 3635 | J12: ='Raw FS'!M13 -> 3831 | K12: ='Raw FS'!N13 -> 3848
B13: Advance from Customers | G13: ='Raw FS'!J14 -> 41 | H13: ='Raw FS'!K14 -> 76 | I13: ='Raw FS'!L14 -> 108 | J13: ='Raw FS'!M14 -> 154 | K13: ='Raw FS'!N14 -> 173
B14: Other Liability items | G14: ='Raw FS'!J15 -> 2613 | H14: ='Raw FS'!K15 -> 2932 | I14: ='Raw FS'!L15 -> 3657 | J14: ='Raw FS'!M15 -> 4017 | K14: ='Raw FS'!N15 -> 3985
B15: Total Current Liabilities | G15: =SUM(G12:G14) -> 6033 | H15: =SUM(H12:H14) -> 7172 | I15: =SUM(I12:I14) -> 7400 | J15: =SUM(J12:J14) -> 8002 | K15: =SUM(K12:K14) -> 8006
A17: # | B17: Net Working Capital | G17: =G9-G15 -> 2934 | H17: =H9-H15 -> 5729 | I17: =I9-I15 -> 6484 | J17: =J9-J15 -> 6382 | K17: =K9-K15 -> 6368
B19: Non Current Assets
B20: Land | G20: ='Raw FS'!J19 -> 644 | H20: ='Raw FS'!K19 -> 644 | I20: ='Raw FS'!L19 -> 804 | J20: ='Raw FS'!M19 -> 1126 | K20: ='Raw FS'!N19 -> 1050
B21: Building | G21: ='Raw FS'!J20 -> 2249 | H21: ='Raw FS'!K20 -> 2325 | I21: ='Raw FS'!L20 -> 2883 | J21: ='Raw FS'!M20 -> 3390 | K21: ='Raw FS'!N20 -> 4136
B22: Plant Machinery | G22: ='Raw FS'!J21 -> 4340 | H22: ='Raw FS'!K21 -> 4531 | I22: ='Raw FS'!L21 -> 4825 | J22: ='Raw FS'!M21 -> 5422 | K22: ='Raw FS'!N21 -> 7576
B23: Equipments | G23: ='Raw FS'!J22 -> 243 | H23: ='Raw FS'!K22 -> 253 | I23: ='Raw FS'!L22 -> 270 | J23: ='Raw FS'!M22 -> 298 | K23: ='Raw FS'!N22 -> 325
B24: Furniture n fittings | G24: ='Raw FS'!J23 -> 99 | H24: ='Raw FS'!K23 -> 113 | I24: ='Raw FS'!L23 -> 146 | J24: ='Raw FS'!M23 -> 175 | K24: ='Raw FS'!N23 -> 203
B25: Vehicles | G25: ='Raw FS'!J24 -> 38 | H25: ='Raw FS'!K24 -> 32 | I25: ='Raw FS'!L24 -> 36 | J25: ='Raw FS'!M24 -> 40 | K25: ='Raw FS'!N24 -> 39
B26: Intangible Assets | G26: ='Raw FS'!J25 -> 476 | H26: ='Raw FS'!K25 -> 345 | I26: ='Raw FS'!L25 -> 422 | J26: ='Raw FS'!M25 -> 850 | K26: ='Raw FS'!N25 -> 827
B27: Other fixed assets | G27: ='Raw FS'!J26 -> 302 | H27: ='Raw FS'!K26 -> 294 | I27: ='Raw FS'!L26 -> 289 | J27: ='Raw FS'!M26 -> 321 | K27: ='Raw FS'!N26 -> 328
B28: Gross Block | G28: =SUM(G20:G27) -> 8391 | H28: =SUM(H20:H27) -> 8537 | I28: =SUM(I20:I27) -> 9675 | J28: =SUM(J20:J27) -> 11622 | K28: =SUM(K20:K27) -> 14484
B29: Acccumulated Depreciation | G29: =-'Raw FS'!J28 -> -2533 | H29: =-'Raw FS'!K28 -> -3019 | I29: =-'Raw FS'!L28 -> -3905 | J29: =-'Raw FS'!M28 -> -4475 | K29: =-'Raw FS'!N28 -> -5264
A30: # | B30: Net Non Current Assets | G30: =SUM(G28:G29) -> 5858 | H30: =SUM(H28:H29) -> 5518 | I30: =SUM(I28:I29) -> 5770 | J30: =SUM(J28:J29) -> 7147 | K30: =SUM(K28:K29) -> 9220
A32: # | B32: Invested Capital | G32: =G30+G17 -> 8792 | H32: =H30+H17 -> 11247 | I32: =I30+I17 -> 12254 | J32: =J30+J17 -> 13529 | K32: =K30+K17 -> 15588
B33: EBIT | G33: =(HistoricalFS!H27+HistoricalFS!H21) -> 4064.33 | H33: =(HistoricalFS!I27+HistoricalFS!I21) -> 3987.25 | I33: =(HistoricalFS!J27+HistoricalFS!J21) -> 5401.82 | J33: =(HistoricalFS!K27+HistoricalFS!K21) -> 6731.98 | K33: =(HistoricalFS!L27+HistoricalFS!L21) -> 4979.87
A35: # | B35: ROIC | G35: =G33/G32 -> 0.46227593 | H35: =H33/H32 -> 0.35451676 | I35: =I33/I32 -> 0.44082096 | J35: =J33/J32 -> 0.49759627 | K35: =K33/K32 -> 0.31946818
A37: # | B37: Calculation of Reinvestment Rate | G37: =G2 -> 44256 | H37: =H2 -> 44621 | I37: =I2 -> 44986 | J37: =J2 -> 45352 | K37: =K2 -> 45717
B39: Net Capex | G39: =-SUM('Raw FS'!J53:J54) -> 261 | H39: =-SUM('Raw FS'!K53:K54) -> 511 | I39: =-SUM('Raw FS'!L53:L54) -> 1420 | J39: =-SUM('Raw FS'!M53:M54) -> 2491 | K39: =-SUM('Raw FS'!N53:N54) -> 1820
B40: Change in Working Capital | H40: =H17-G17 -> 2795 | I40: =I17-H17 -> 755 | J40: =J17-I17 -> -102 | K40: =K17-J17 -> -14
B42: EBIT | G42: =G33 -> 4064.33 | H42: =H33 -> 3987.25 | I42: =I33 -> 5401.82 | J42: =J33 -> 6731.98 | K42: =K33 -> 4979.87
B43: Marginal Tax Rate | G43: 0.25 | H43: 0.25 | I43: 0.25 | J43: 0.25 | K43: 0.25
B44: EBIT(1-T) | G44: =G42*(1-G43) -> 3048.2475 | H44: =H42*(1-H43) -> 2990.4375 | I44: =I42*(1-I43) -> 4051.365 | J44: =J42*(1-J43) -> 5048.985 | K44: =K42*(1-K43) -> 3734.9025
B46: Reinvestment | H46: =SUM(H39:H40) -> 3306 | I46: =SUM(I39:I40) -> 2175 | J46: =SUM(J39:J40) -> 2389 | K46: =SUM(K39:K40) -> 1806
B48: Reinvestment Rate | H48: =H46/H44 -> 1.1055239 | I48: =I46/I44 -> 0.5368561 | J48: =J46/J44 -> 0.47316441 | K48: =K46/K44 -> 0.48354676
J50: 4 Year Average | K50: =AVERAGE(H48:K48) -> 0.64977278
J51: 4 Year Median | K51: =MEDIAN(H48:K48) -> 0.51020143
A53: # | B53: Calculation of Growth Rate | G53: =G37 -> 44256 | H53: =H37 -> 44621 | I53: =I37 -> 44986 | J53: =J37 -> 45352 | K53: =K37 -> 45717
B55: Reinvestment Rate | H55: =H48 -> 1.1055239 | I55: =I48 -> 0.5368561 | J55: =J48 -> 0.47316441 | K55: =K48 -> 0.48354676
...

Sheet Raw FS
B2: Particulars | C2: 41699 | D2: 42064 | E2: 42430 | F2: 42795 | G2: 43160 | H2: 43525 | I2: 43891 | J2: 44256 | K2: 44621 | L2: 44986 | M2: 45352 | N2: 45717
B4: Equity Capital | C4: 96 | D4: 96 | E4: 96 | F4: 96 | G4: 96 | H4: 96 | I4: 96 | J4: 96 | K4: 96 | L4: 96 | M4: 96 | N4: 96
B5: Reserves | C5: 3943 | D5: 4646 | E5: 6429 | F5: 7508 | G5: 8314 | H5: 9375 | I5: 10034 | J5: 12710 | K5: 13716 | L5: 15896 | M5: 18632 | N5: 19304
B6: Borrowings -
B7: Long term Borrowings | C7: 41 | D7: 78 | E7: 73 | F7: 41 | G7: 28 | H7: 19 | I7: 19 | J7: 15 | K7: 45 | L7: 76 | M7: 54 | N7: 260
B8: Short term Borrowings | C8: 199 | D8: 332 | E8: 231 | F8: 504 | G8: 492 | H8: 597 | I8: 321 | J8: 326 | K8: 731 | L8: 896 | M8: 1053 | N8: 604
B9: Lease Liabilities | C9: 0 | D9: 0 | E9: 0 | F9: 0 | G9: 0 | H9: 693 | I9: 764 | J9: 745 | K9: 811 | L9: 960 | M9: 1367 | N9: 1427
B10: Other Borrowings | C10: 9 | D10: 8 | E10: 20 | F10: 15 | G10: 13 | H10: 11 | I10: 15 | J10: 8 | K10: 0 | L10: 0 | M10: 0 | N10: 0
B11: Other Liabilities -
B12: Non controlling int | C12: 246 | D12: 264 | E12: 384 | F12: 375 | G12: 328 | H12: 361 | I12: 404 | J12: 423 | K12: 388 | L12: 454 | M12: 695 | N12: 659
B13: Trade Payables | C13: 1746 | D13: 1549 | E13: 1565 | F13: 1923 | G13: 2160 | H13: 2394 | I13: 2137 | J13: 3379 | K13: 4164 | L13: 3635 | M13: 3831 | N13: 3848
B14: Advance from Customers | C14: 0 | D14: 5 | E14: 12 | F14: 17 | G14: 16 | H14: 13 | I14: 29 | J14: 41 | K14: 76 | L14: 108 | M14: 154 | N14: 173
B15: Other liability items | C15: 1795 | D15: 1937 | E15: 1750 | F15: 1925 | G15: 2316 | H15: 2690 | I15: 2320 | J15: 2613 | K15: 2932 | L15: 3657 | M15: 4017 | N15: 3985
B16: Total Liabilities | C16: 8075 | D16: 8914 | E16: 10559 | F16: 12405 | G16: 13763 | H16: 16249 | I16: 16138 | J16: 20355 | K16: 22958 | L16: 25779 | M16: 29901 | N16: 30355
B18: Fixed Assets -
B19: Land | C19: 247 | D19: 251 | E19: 429 | F19: 408 | G19: 586 | H19: 605 | I19: 640 | J19: 644 | K19: 644 | L19: 804 | M19: 1126 | N19: 1050
B20: Building | C20: 931 | D20: 962 | E20: 923 | F20: 931 | G20: 957 | H20: 2402 | I20: 2257 | J20: 2249 | K20: 2325 | L20: 2883 | M20: 3390 | N20: 4136
B21: Plant Machinery | C21: 2054 | D21: 2132 | E21: 1793 | F21: 1980 | G21: 2157 | H21: 4006 | I21: 4208 | J21: 4340 | K21: 4531 | L21: 4825 | M21: 5422 | N21: 7576
B22: Equipments | C22: 155 | D22: 171 | E22: 97 | F22: 119 | G22: 200 | H22: 221 | I22: 241 | J22: 243 | K22: 253 | L22: 270 | M22: 298 | N22: 325
B23: Furniture n fittings | C23: 71 | D23: 83 | E23: 49 | F23: 59 | G23: 72 | H23: 88 | I23: 94 | J23: 99 | K23: 113 | L23: 146 | M23: 175 | N23: 203
B24: Vehicles | C24: 14 | D24: 18 | E24: 11 | F24: 14 | G24: 27 | H24: 47 | I24: 43 | J24: 38 | K24: 32 | L24: 36 | M24: 40 | N24: 39
B25: Intangible Assets | C25: 203 | D25: 351 | E25: 339 | F25: 276 | G25: 468 | H25: 512 | I25: 505 | J25: 476 | K25: 345 | L25: 422 | M25: 850 | N25: 827
B26: Other fixed assets | C26: 128 | D26: 145 | E26: 103 | F26: 128 | G26: 238 | H26: 261 | I26: 293 | J26: 302 | K26: 294 | L26: 289 | M26: 321 | N26: 328
B27: Gross Block | C27: 3804 | D27: 4112 | E27: 3744 | F27: 3914 | G27: 4705 | H27: 8141 | I27: 8282 | J27: 8392 | K27: 8538 | L27: 9676 | M27: 11622 | N27: 14484
B28: Accumulated Depreciation | C28: 1242 | D28: 1452 | E28: 327 | F28: 610 | G28: 973 | H28: 1644 | I28: 2010 | J28: 2533 | K28: 3019 | L28: 3905 | M28: 4475 | N28: 5264
B29: Net Block | C29: =C27-C28 -> 2562 | D29: =D27-D28 -> 2660 | E29: =E27-E28 -> 3417 | F29: =F27-F28 -> 3304 | G29: =G27-G28 -> 3732 | H29: =H27-H28 -> 6497 | I29: =I27-I28 -> 6272 | J29: =J27-J28 -> 5859 | ... N29: =N27-N28 -> 9220
B31: CWIP | C31: 72 | D31: 196 | E31: 107 | F31: 258 | G31: 1405 | H31: 210 | I31: 140 | J31: 183 | K31: 426 | L31: 1020 | M31: 2698 | N31: 1254
B32: Investments | C32: 1424 | D32: 1588 | E32: 2712 | F32: 2652 | G32: 2141 | H32: 2569 | I32: 2019 | J32: 4737 | K32: 3248 | L32: 4262 | M32: 4588 | N32: 4725
B34: Other Assets -
B35: Inventories | C35: 2070 | D35: 2259 | E35: 1998 | F35: 2627 | G35: 2658 | H35: 3150 | I35: 3390 | J35: 3799 | K35: 6153 | L35: 6211 | M35: 5923 | N35: 6719
B36: Trade receivables + | C36: 1110 | D36: 1182 | E36: 1187 | F36: 1447 | G36: 1731 | H36: 1907 | I36: 1795 | J36: 2602 | K36: 3871 | L36: 4637 | M36: 4889 | N36: 4314
B37: Cash Equivalents | C37: 229 | D37: 204 | E37: 424 | F37: 801 | G37: 405 | H37: 445 | I37: 783 | J37: 611 | K37: 864 | L37: 844 | M37: 1084 | N37: 782
B38: Loans n Advances | C38: 7 | D38: 8 | E38: 9 | F38: 14 | G38: 13 | H38: 16 | I38: 12 | J38: 12 | K38: 8 | L38: 12 | M38: 17 | N38: 22
B39: Other asset items | C39: 603 | D39: 817 | E39: 705 | F39: 1303 | G39: 1678 | H39: 1456 | I39: 1727 | J39: 2554 | K39: 2869 | L39: 3024 | M39: 3555 | N39: 3319
B40: Total Assets | C40: 8075 | D40: 8914 | E40: 10559 | F40: 12405 | G40: 13763 | H40: 16249 | I40: 16138 | J40: 20355 | K40: 22958 | L40: 25779 | M40: 29901 | N40: 30355
B44: Cash from Operating Activity - | C44: 1402 | D44: 1188 | E44: 2243 | F44: 1527 | G44: 2113 | H44: 2470 | I44: 3038 | J44: 3683 | K44: 986 | L44: 4193 | M44: 6104 | N44: 4424
B45: Profit from operations | C45: 2051 | D45: 2271 | E45: 2848 | F45: 3056 | G45: 3274 | H45: 3861 | I45: 4380 | J45: 4970 | K45: 4957 | L45: 6460 | M45: 7929 | N45: 6390
B46: Receivables | C46: -254 | D46: -155 | E46: -146 | F46: -475 | G46: -483 | H46: -205 | I46: 160 | J46: -1342 | K46: -1326 | L46: -834 | M46: -362 | N46: 282
B47: Inventory | C47: -231 | D47: -144 | E47: 202 | F47: -629 | G47: -39 | H47: -492 | I47: -251 | J47: -409 | K47: -2354 | L47: -56 | M47: 315 | N47: -805
B48: Payables | C48: 317 | D48: -151 | E48: 142 | F48: 501 | G48: 442 | H48: 287 | I48: -241 | J48: 1544 | K48: 644 | L48: -539 | M48: 269 | N48: -160
...

Sheet DCF
B2: Calculation PV of FCFF | E2: ='Intrisic Growth'!K2 -> 45717 | F2: =E2+365 -> 46082 | G2: =F2+366 -> 46448 | H2: =G2+365 -> 46813 | I2: =H2+365 -> 47178 | J2: =I2+365 -> 47543
B4: EBIT | E4: ='Data Sheet'!K33-'Data Sheet'!K26 -> 5287.61 | F4: =E4*(1+$D$14) -> 5922.1232 | G4: =F4*(1+$D$14) -> 6632.778 | H4: =G4*(1+$D$14) -> 7428.7113 | I4: =H4*(1+$D$14) -> 8320.1567 | J4: =I4*(1+$D$14) -> 9318.5755
B5: Tax Rate | E5: 0.25 | F5: =E5 -> 0.25 | G5: =F5 -> 0.25 | H5: =G5 -> 0.25 | I5: =H5 -> 0.25 | J5: =I5 -> 0.25
B6: EBIT(1-T) | E6: =E4*(1-E5) -> 3965.7075 | F6: =F4*(1-F5) -> 4441.5924 | G6: =G4*(1-G5) -> 4974.5835 | H6: =H4*(1-H5) -> 5571.5335 | I6: =I4*(1-I5) -> 6240.1175 | J6: =J4*(1-J5) -> 6988.9316
B7: Less: Reinvestment Rate | E7: ='Intrisic Growth'!K51 -> 0.51020143 | F7: =((E7+($J$7-$E$7)/4)) -> 0.51800107 | G7: =((F7+($J$7-$E$7)/4)) -> 0.52580071 | H7: =((G7+($J$7-$E$7)/4)) -> 0.53360036 | I7: =((H7+($J$7-$E$7)/4)) -> 0.5414 | J7: =54.14% -> 0.5414
B8: Free Cash Flow To Firm(FCFF) | E8: =E6*(1-E7) -> 1942.3979 | F8: =F6*(1-F7) -> 2140.8428 | G8: =G6*(1-G7) -> 2358.9439 | H8: =H6*(1-H7) -> 2598.5612 | I8: =I6*(1-I7) -> 2861.7179 | J8: =J6*(1-J7) -> 3205.124
B9: Mid Year Convention | F9: =0.5 -> 0.5 | G9: =1+F9 -> 1.5 | H9: =1+G9 -> 2.5 | I9: =1+H9 -> 3.5 | J9: =1+I9 -> 4.5
B10: Discounting Factor | F10: =1/(1+$D$16)^F9 -> 0.93057887 | G10: =1/(1+$D$16)^G9 -> 0.80585992 | H10: =1/(1+$D$16)^H9 -> 0.69785618 | I10: =1/(1+$D$16)^I9 -> 0.60432742 | J10: =1/(1+$D$16)^J9 -> 0.52333366
B12: PV of FCFF | F12: =F8*F10 -> 1992.223 | G12: =G8*G10 -> 1900.9784 | H12: =H8*H10 -> 1813.422 | I12: =I8*I10 -> 1729.4146 | J12: =J8*J10 -> 1677.3493
B14: Expected Growth | D14: 0.12
B15: Terminal Growth | D15: 0.052
B16: WACC | D16: =WACC!K42 -> 0.15476504
B18: Calculation of Terminal Value | F18: Sensitivity Analysis
F19: =D37 -> 284.70872 | G19: 0.13 | H19: 0.1548 | I19: 0.17 | J19: 0.19
B20: FCFF(n+1) | D20: =J8*(1+D14) -> 3589.7389 | F20: 0.03 | G20: 289.97789 | H20: 251.06239 | I20: 234.02565 | J20: 216.54057
B21: WACC | D21: =D16 -> 0.15476504 | F21: 0.04 | G21: 311.73709 | H21: 264.73115 | I21: 244.78569 | J21: 224.70028
